<robot name="human_wb_ISB_model">
    <material name="body_color">
        <texture />
        <color rgba="0.005 0.005 0.005 0.6" />
    </material>
    <link name="pelvis">
        <inertial>
            <mass value="13.3963" />
            <origin xyz="-0.07526 -0.027216 -0.000567" rpy="0 -0 0" />
            <inertia ixx="0.134392" ixy="0.0068219" ixz="0.00172127" iyy="0.134423" iyz="0.000558921" izz="0.120176" />
        </inertial>
        <visual>
	        <origin xyz="-0.08 -0.13 0.125" rpy="0 1.57 0" /> 
            <geometry>
		        <mesh filename="package://human_urdf/meshes/pelvis_mesh.STL" scale="0.006 0.0055 0.0055"/>
            </geometry>
            <material name="body_color">
                <texture />
                <color rgba="0 1 1 0.5" />
            </material>
        </visual>
    </link>
    <joint name="middle_lumbar_Z" type="revolute">
        <origin xyz="0 0 0" rpy="0 -0 0" />
        <axis xyz="0 0 1" />
        <parent link="pelvis" />
        <child link="torso_z" />
        <limit effort="0" velocity="0" lower="-3.14159" upper="0.785398" />
    </joint>
    <link name="torso_z" />
    <joint name="middle_lumbar_Y" type="revolute">
        <origin xyz="0 0 0" rpy="0 -0 0" />
        <axis xyz="1 0 0" />
        <parent link="torso_z" />
        <child link="torso" />
        <limit effort="0" velocity="0" lower="-0.785398" upper="0.785398" />
    </joint>
    <link name="torso" >
        <inertial>
            <mass value="28.6794" />
            <origin xyz="0 0.188511 -0.00135864" rpy="0 -0 0" />
            <inertia ixx="1.60287" ixy="0.0400354" ixz="0.000330871" iyy="0.360371" iyz="-0.00436749" izz="1.44797" />
        </inertial>
        <visual>
            <origin xyz="-0.05 0.05 -0.085" rpy="0 -0 0" />
            <geometry>
		        <mesh filename="package://human_urdf/meshes/abdomen_mesh.STL" scale="0.0055 0.0055 0.0055"/>
                <!--<box size="0.15 0.161217 0.198658" />-->
            </geometry>
            <material name="body_color">
                <texture />
                <color rgba="0 1 1 0.5" />
            </material>
        </visual>
        <visual>
	    <origin xyz="-0.115 0.17 0.125" rpy="0 1.57 0" /> 
            <geometry>
		        <!--<box size="0.15 0.356643 0.329994" />-->
		        <mesh filename="package://human_urdf/meshes/torso_mesh.STL" scale="0.0065 0.0065 0.0065"/>
            </geometry>
            <material name="body_color">
                <texture />
                <color rgba="0.2 0.2 0.2 0.2" />
            </material>
        </visual>
    </link>
    <joint name="right_shoulder_Z" type="revolute">
        <origin xyz="0.00805 0.4067 0.2037" rpy="0 -0 0" />
        <axis xyz="0 0 1" />
        <parent link="torso" />
        <child link="upperarm_z_R" />
        <limit effort="0" velocity="0" lower="-2.0944" upper="0.392699" />
    </joint>
    <link name="upperarm_z_R">
        <visual>
	        <origin xyz="-0.15 -0.04 -0.05" rpy="0 0 0" /> 
            <geometry>
		        <mesh filename="package://human_urdf/meshes/shoulder_mesh.STL" scale="0.0055 0.0055 0.0055"/>
            </geometry>
            <material name="body_color">
                <texture />
                <color rgba="0 1 1 0.5" />
            </material>
        </visual>
    </link>
    <joint name="right_shoulder_X" type="revolute">
        <origin xyz="0 0 0" rpy="0 -0 0" />
        <axis xyz="1 0 0" />
        <parent link="upperarm_z_R" />
        <child link="upperarm_x_R" />
        <limit effort="0" velocity="0" lower="-3.14159" upper="1.0472" />
    </joint>
    <link name="upperarm_x_R" />
    <joint name="right_shoulder_Y" type="revolute">
        <origin xyz="0 0 0" rpy="0 -0 0" />
        <axis xyz="0 1 0" />
        <parent link="upperarm_x_R" />
        <child link="upperarmR" />
        <limit effort="0" velocity="0" lower="-1.5708" upper="3.14159" />
    </joint>
    <link name="upperarmR">
        <inertial>
            <mass value="2.26416" />
            <origin xyz="0.00506736 -0.135693 -0.00872712" rpy="0 -0 0" />
            <inertia ixx="0.0569524" ixy="0.00200545" ixz="0.000261627" iyy="0.00326316" iyz="0.000351349" izz="0.0578968" />
        </inertial>
        <visual>
            <origin xyz="-0.065 -0.27 0.18" rpy="0.0 1.57 0" />
            <geometry>
                <mesh filename="package://human_urdf/meshes/upperarm_mesh.STL" scale="0.0063 0.0060 0.007"/>
            </geometry>
            <material name="body_color">
                <texture />
                <color rgba="0 1 1 0.5" />
            </material>
        </visual>
    </link>
    <joint name="right_elbow_Z" type="revolute">
        <origin xyz="0 -0.2737 0" rpy="0 -0 0" />
        <axis xyz="0 0 1" />
        <parent link="upperarmR" />
        <child link="lowerarm_z" />
        <limit effort="0" velocity="0" lower="0" upper="2.74889" />
    </joint>
    <link name="lowerarm_z">
        <visual>
	        <origin xyz="-0.15 -0.04 -0.035" rpy="0 0 0" /> 
            <geometry>
		        <mesh filename="package://human_urdf/meshes/elbow_mesh.STL" scale="0.0055 0.0055 0.0055"/>
            </geometry>
            <material name="body_color">
                <texture />
                <color rgba="0 1 1 0.5" />
            </material>
        </visual>
    </link>
    <joint name="right_elbow_Y" type="revolute">
        <origin xyz="0 0 0" rpy="0 -0 0" />
        <axis xyz="0 1 0" />
        <parent link="lowerarm_z" />
        <child link="lowerarmR" />
        <limit effort="0" velocity="0" lower="-1.5708" upper="1.5708" />
    </joint>
    <link name="lowerarmR">
        <inertial>
            <mass value="1.60378" />
            <origin xyz="-0.00373932 -0.119946 0.00316404" rpy="0 -0 0" />
            <inertia ixx="0.0334927" ixy="0.000129905" ixz="3.22441e-05" iyy="0.00164405" iyz="0.000661733" izz="0.033499" />
        </inertial>
        <visual>
            <origin xyz="0.052 -0.26 -0.17" rpy="0.0 -1.57 0" />
            <geometry>
                <mesh filename="package://human_urdf/meshes/lowerarm_mesh.STL" scale="0.0060 0.0060 0.0060"/>
            </geometry>
            <material name="body_color">
                <texture />
                <color rgba="0 1 1 0.5" />
            </material>
        </visual>
    </link>
    <joint name="left_shoulder_Z" type="revolute">
        <origin xyz="0.00805 0.4067 -0.2037" rpy="0 -0 0" />
        <axis xyz="0 0 1" />
        <parent link="torso" />
        <child link="upperarm_z_L" />
        <limit effort="0" velocity="0" lower="-2.0944" upper="0.392699" />
    </joint>
    <link name="upperarm_z_L">
	    <visual>
	        <origin xyz="-0.16 -0.045 -0.045" rpy="0 0 0" /> 
            <geometry>
		        <mesh filename="package://human_urdf/meshes/shoulder_mesh.STL" scale="0.0055 0.0055 0.0055"/>
            </geometry>
            <material name="body_color">
                <texture />
                <color rgba="0 1 1 0.5" />
            </material>
        </visual>
    </link>
    <joint name="left_shoulder_X" type="revolute">
        <origin xyz="0 0 0" rpy="0 -0 0" />
        <axis xyz="1 0 0" />
        <parent link="upperarm_z_L" />
        <child link="upperarm_x_L" />
        <limit effort="0" velocity="0" lower="-3.14159" upper="1.0472" />
    </joint>
    <link name="upperarm_x_L" />
    <joint name="left_shoulder_Y" type="revolute">
        <origin xyz="0 0 0" rpy="0 -0 0" />
        <axis xyz="0 1 0" />
        <parent link="upperarm_x_L" />
        <child link="upperarmL" />
        <limit effort="0" velocity="0" lower="-1.5708" upper="3.14159" />
    </joint>
    <link name="upperarmL">
        <inertial>
            <mass value="2.26416" />
            <origin xyz="0.00506736 -0.135693 0.00872712" rpy="0 -0 0" />
            <inertia ixx="0.0569524" ixy="0.00200545" ixz="-0.000261627" iyy="0.00326316" iyz="-0.000351349" izz="0.0578968" />
        </inertial>
        <visual>
            <origin xyz="-0.065 -0.27 0.18" rpy="0.0 1.57 0" />
            <geometry>
                <mesh filename="package://human_urdf/meshes/upperarm_mesh.STL" scale="0.0063 0.0060 0.007"/>
            </geometry>
            <material name="body_color"/>
        </visual>
    </link>
    <joint name="left_elbow_Z" type="revolute">
        <origin xyz="0 -0.2737 0" rpy="0 -0 0" />
        <axis xyz="0 0 1" />
        <parent link="upperarmL" />
        <child link="lowerarm_z_L" />
        <limit effort="0" velocity="0" lower="0" upper="2.74889" />
    </joint>
    <link name="lowerarm_z_L">
	    <visual>
	        <origin xyz="-0.15 -0.04 -0.035" rpy="0 0 0" /> 
            <geometry>
		        <mesh filename="package://human_urdf/meshes/elbow_mesh.STL" scale="0.0055 0.0055 0.0055"/>
            </geometry>
            <material name="body_color">
                <texture />
                <color rgba="0 1 1 0.5" />
            </material>
        </visual>
    </link>
    <joint name="left_elbow_Y" type="revolute">
        <origin xyz="0 0 0" rpy="0 -0 0" />
        <axis xyz="0 1 0" />
        <parent link="lowerarm_z_L" />
        <child link="lowerarmL" />
        <limit effort="0" velocity="0" lower="-1.5708" upper="1.5708" />
    </joint>
    <link name="lowerarmL">
        <inertial>
            <mass value="1.60378" />
            <origin xyz="-0.00373932 -0.119946 -0.00316404" rpy="0 -0 0" />
            <inertia ixx="0.0334927" ixy="0.000129905" ixz="-3.22441e-05" iyy="0.00164405" iyz="-0.000661733" izz="0.033499" />
        </inertial>
        <visual>
            <origin xyz="0.052 -0.26 -0.17" rpy="0.0 -1.57 0" />
            <geometry>
                <mesh filename="package://human_urdf/meshes/lowerarm_mesh.STL" scale="0.0060 0.0060 0.0060"/>
            </geometry>
            <material name="body_color">
                <texture />
                <color rgba="0 1 1 0.5" />
            </material>
        </visual>
    </link>
    <joint name="right_hip_Z" type="revolute">
        <origin xyz="0.053375 -0.0749 0.079975" rpy="0 -0 0" />
        <axis xyz="0 0 1" />
        <parent link="pelvis" />
        <child link="thigh_z" />
        <limit effort="0" velocity="0" lower="-0.785398" upper="3.14159" />
    </joint>
    <link name="thigh_z" />
    <joint name="right_hip_X" type="revolute">
        <origin xyz="0 0 0" rpy="0 -0 0" />
        <axis xyz="1 0 0" />
        <parent link="thigh_z" />
        <child link="thigh_x" />
        <limit effort="0" velocity="0" lower="-0.392699" upper="1.5708" />
    </joint>
    <link name="thigh_x">
        <visual>
            <origin xyz="-0.04 -0.48 0.07" rpy="0.0 1.57 0" />
            <geometry>
                <mesh filename="package://human_urdf/meshes/knee_mesh.STL" scale="0.006 0.006 0.006"/>
            </geometry>
            <material name="body_color">
                <texture />
                <color rgba="0 1 1 0.5" />
            </material>
        </visual>
    </link>
    <joint name="right_hip_Y" type="revolute">
        <origin xyz="0 0 0" rpy="0 -0 0" />
        <axis xyz="0 1 0" />
        <parent link="thigh_x" />
        <child link="thighR" />
        <limit effort="0" velocity="0" lower="-1.5708" upper="1.5708" />
    </joint>
    <link name="thighR">
        <inertial>
            <mass value="11.6038" />
            <origin xyz="-0.0180072 -0.188417 -0.0144936" rpy="0 -0 0" />
            <inertia ixx="0.602628" ixy="-0.0284023" ixz="-0.00213314" iyy="0.0565628" iyz="-0.0207203" izz="0.617159" />
        </inertial>
        <visual>
            <origin xyz="-0.1 -0.42 0.07" rpy="0.0 1.57 0" />
            <geometry>
                <mesh filename="package://human_urdf/meshes/upperleg_mesh.STL" scale="0.0063 0.0065 0.007"/>
            </geometry>
            <material name="body_color">
                <texture />
                <color rgba="0 1 1 0.5" />
            </material>
        </visual>
    </link>
    <joint name="right_knee_Z" type="revolute">
        <origin xyz="0 -0.427 0" rpy="0 -0 0" />
        <axis xyz="0 0 1" />
        <parent link="thighR" />
        <child link="shankR" />
        <limit effort="0" velocity="0" lower="0" upper="2.74889" />
    </joint>
    <link name="shankR">
        <inertial>
            <mass value="4.52832" />
            <origin xyz="-0.0211334 -0.180515 0.00308196" rpy="0 -0 0" />
            <inertia ixx="0.21642" ixy="-0.0158706" ixz="0.00064606" iyy="0.0108434" iyz="0.00392376" izz="0.2184" />
        </inertial>
        <visual>
            <origin xyz="-0.06 -0.43 0.07" rpy="0.0 1.57 0" />
            <geometry>
                <mesh filename="package://human_urdf/meshes/lowerleg_mesh.STL" scale="0.0063 0.0065 0.007"/>
            </geometry>
            <material name="body_color">
                <texture />
                <color rgba="0 1 1 0.5" />
            </material>
        </visual>
    </link>
    <joint name="right_ankle_Z" type="revolute">
        <origin xyz="0 -0.42805 0" rpy="0 -0 0" />
        <axis xyz="0 0 1" />
        <parent link="shankR" />
        <child link="footR" />
        <limit effort="0" velocity="0" lower="-1.0472" upper="0.392699" />
    </joint>
    <link name="footR">
        <inertial>
            <mass value="1.13208" />
            <origin xyz="0.0709326 -0.0281187 0.0048042" rpy="0 -0 0" />
            <inertia ixx="0.00201519" ixy="0.00291119" ixz="-0.000112291" iyy="0.011149" iyz="0.00015293" izz="0.0117988" />
        </inertial>
        <visual>
            <origin xyz="-0.05 -0.055 0.065" rpy="0 1.57 0" />
            <geometry>
		        <mesh filename="package://human_urdf/meshes/foot_mesh.STL" scale="0.0060 0.0060 0.0060"/>
                <!--<box size="0.03 0.085239 0.06" />-->
            </geometry>
            <material name="body_color">
                <texture />
                <color rgba="0 1 1 0.5" />
            </material>
        </visual>
    </link>
    <joint name="left_hip_Z" type="revolute">
        <origin xyz="0.053375 -0.0749 -0.079975" rpy="0 -0 0" />
        <axis xyz="0 0 1" />
        <parent link="pelvis" />
        <child link="thigh_z_L" />
        <limit effort="0" velocity="0" lower="-0.785398" upper="3.14159" />
    </joint>
    <link name="thigh_z_L" />
    <joint name="left_hip_X" type="revolute">
        <origin xyz="0 0 0" rpy="0 -0 0" />
        <axis xyz="1 0 0" />
        <parent link="thigh_z_L" />
        <child link="thigh_x_L" />
        <limit effort="0" velocity="0" lower="-0.392699" upper="1.5708" />
    </joint>
    <link name="thigh_x_L">
	    <visual>
            <origin xyz="-0.04 -0.48 0.080" rpy="0.0 1.57 0" />
            <geometry>
                <mesh filename="package://human_urdf/meshes/knee_mesh.STL" scale="0.006 0.006 0.006"/>
            </geometry>
            <material name="body_color">
                <texture />
                <color rgba="0 1 1 0.5" />
            </material>
        </visual>
    </link>
    <joint name="left_hip_Y" type="revolute">
        <origin xyz="0 0 0" rpy="0 -0 0" />
        <axis xyz="0 1 0" />
        <parent link="thigh_x_L" />
        <child link="thighL" />
        <limit effort="0" velocity="0" lower="-1.5708" upper="1.5708" />
    </joint>
    <link name="thighL">
        <inertial>
            <mass value="11.6038" />
            <origin xyz="-0.0180072 -0.188417 0.0144936" rpy="0 -0 0" />
            <inertia ixx="0.602628" ixy="-0.0284023" ixz="0.00213314" iyy="0.0565628" iyz="0.0207203" izz="0.617159" />
        </inertial>
        <visual>
            <origin xyz="-0.1 -0.42 0.085" rpy="0.0 1.57 0" />
            <geometry>
                <mesh filename="package://human_urdf/meshes/upperleg_mesh.STL" scale="0.0063 0.0065 0.007"/>
            </geometry>
            <material name="body_color">
                <texture />
                <color rgba="0 1 1 0.5" />
            </material>
        </visual>
    </link>
    <joint name="left_knee_Z" type="revolute">
        <origin xyz="0 -0.427 0" rpy="0 -0 0" />
        <axis xyz="0 0 1" />
        <parent link="thighL" />
        <child link="shankL" />
        <limit effort="0" velocity="0" lower="0" upper="2.74889" />
    </joint>
    <link name="shankL">
        <inertial>
            <mass value="4.52832" />
            <origin xyz="-0.0211334 -0.180515 -0.00308196" rpy="0 -0 0" />
            <inertia ixx="0.21642" ixy="-0.0158706" ixz="-0.00064606" iyy="0.0108434" iyz="-0.00392376" izz="0.2184" />
        </inertial>
        <visual>
            <origin xyz="-0.06 -0.43 0.08" rpy="0.0 1.57 0" />
            <geometry>
                <mesh filename="package://human_urdf/meshes/lowerleg_mesh.STL" scale="0.0063 0.0065 0.007"/>
            </geometry>
            <material name="body_color">
                <texture />
                <color rgba="0 1 1 0.5" />
            </material>        
	    </visual>
    </link>
    <joint name="left_ankle_Z" type="revolute">
        <origin xyz="0 -0.42805 0" rpy="0 -0 0" />
        <axis xyz="0 0 1" />
        <parent link="shankL" />
        <child link="footL" />
        <limit effort="0" velocity="0" lower="-0.392699" upper="1.0472" />
    </joint>
    <link name="footL">
        <inertial>
            <mass value="1.13208" />
            <origin xyz="0.0709326 -0.0281187 -0.0048042" rpy="0 -0 0" />
            <inertia ixx="0.00201519" ixy="0.00291119" ixz="0.000112291" iyy="0.011149" iyz="-0.00015293" izz="0.0117988" />
        </inertial>
        <visual>
            <origin xyz="-0.05 -0.055 0.075" rpy="0 1.57 0" />
            <geometry>
		        <mesh filename="package://human_urdf/meshes/foot_mesh.STL" scale="0.0060 0.0060 0.0060"/>
                <!--<box size="0.03 0.085239 0.06" />-->
            </geometry>
            <material name="body_color">
                <texture />
                <color rgba="0 1 1 0.5" />
            </material>
        </visual>
    </link>
</robot>
